Workbook

Sheet Từ viết tắt
B1: Từ viết tắt | C1: Tên Tiếng Anh | D1: Tiếng Việt
B2: CORSIA | C2: Carbon Offsetting and Reduction Scheme
B3: EU-ETS | C3: EU Emissions Trading System
B4: UK-ETS | C4: UK Emissions Trading Scheme
A5: 1 | B5: {=_xlfn.UNIQUE('Nguồn dữ liệu'!C2:C102)} -> Report Pro | D5: Hệ thống báo cáo phục vụ Khối DV của TCT
A6: 2 | B6: CLM | D6: Hệ thống quản lý khách hàng thường xuyên
A7: 3 | B7: FIMS | D7: Phần mềm khai thác dữ liệu chuyến bay phục vụ điều hành khai thác
A8: 4 | B8: EU-ETS | D8: Phần mềm
A9: 5 | B9: PMS | D9: Phần mềm kế hoạch ngắn hạn
A10: 6 | B10: CMS | D10: Phần mềm quản lý hợp đồng
A11: 7 | B11: SkyHR | D11: Phần mềm Quản trị nhân lực
A12: 8 | B12: TOSS
A13: 8 | B13: Netlines | D13: Hệ thống điều hành bay
A14: 9 | B14: RPS | D14: Hệ thống phân tích hiệu quả đường bay
A15: 10 | B15: VHAT | D15: Website Văn hóa an toàn
A16: 11 | B16: LMS | D16: Phần mềm quản lý chuỗi cung ứng vật tư vật phẩm phục vụ hành khách
A17: 12 | B17: ANCM | D17: Phần mềm quản lý quy trình kiểm soát và thanh toán chi phí điều hành bay, bay qua, hạ cất cánh

Sheet 95 Chỉ tiêu
Q1: UAT | W1: Quản lý KPI
S2: Quản lý KPI
A3: STT | B3: PIC CQĐV | C3: PIC VNA | D3: Phase | E3: Mã GRI (GRI Code) | F3: Trụ cột | G3: Topic | H3: Tên chỉ tiêu (VN) | I3: Tên chỉ tiêu (EN) | J3: Disclosure (Vi) | K3: Disclosure (En) | L3: Yêu cầu của GRI | M3: Note | N3: Nguồn dữ liệu | O3: Biểu mẫu | P3: Mức độ ưu tiên | Q3: Nhập liệu | R3: Dashboard | S3: Có KPI (Yes/No) | T3: Mã KPI | U3: Tên KPI | V3: KPI đạt khi | W3: Nguồn lấy dữ liệu KH/mục tiêu (KPI) | X3: KPI nhập dữ liệu theo tháng/ năm | Y3: Có đưa KPI lên báo cáo nội bộ không (Yes/No) | Z3: Ghi chú | AA3: Công thức tính toán có hệ số
A4: =ROW()-2 -> 2 | B4: Tổ dịch vụ | C4: MS Hương | D4: Phase 1 | E4: Airline B-1 | F4: Social | G4: Customer Experience | H4: Sự hài lòng của khách hàng (NPS Net Promotor Score) | I4: Customer satisfaction (NPS Net Promotor Score) | K4: Customer satisfaction | M4: Dashboard | N4: Report Pro | Q4: N/A | R4: 2 | S4: Yes | T4: 1. Airline B-1-01 2. Airline B-1-02 | U4: 1. NPS (DOM) 2. NPS (INT) | V4: ≥ KH | W4: Nhập thủ công | X4: - Năm | Y4: Yes | Z4: Note: có 2 KPI cho từng phạm vi DOM và INT
A5: =ROW()-2 -> 3 | B5: TTBSV | D5: Phase 1 | E5: Airline B-2 | F5: Social | G5: Customer Experience | K5: Customer engagement | M5: Dashboard | N5: CLM | Q5: N/A | R5: 1 | S5: No | T5: Airline B-2 | U5: Customer engagement/Tương tác khách hàng | V5: > KH | Y5: No | Z5: Không cung cấp do số liệu nhạy cảm
A6: =ROW()-2 -> 4 | B6: TCNL | D6: Phase 1 | E6: Airline D-1 | F6: Social | G6: Labor Conditions | H6: Ngày công mất do đình công | I6: Working days lost to strikes | K6: Working days lost to strikes | M6: Dashboard | N6: Excel | O6: Airline D-1 Số vụ đình công | P6: 1 | Q6: 1 | R6: 1 | S6: Yes | T6: Airline D-1 | U6: Số ngày công mất do đình công | V6: = KH | W6: Nhập thủ công | X6: - Năm | Y6: No
A7: =ROW()-2 -> 5 | B7: Ban ATCL | C7: Mr Đàn | D7: Phase 1 | E7: Airline E-1 | F7: Environment | G7: Noise | H7: Tiếng ồn | I7: Noise Compliance | J7: Tiếng ồn | K7: Noise | M7: Dashboard | N7: Excel | O7: Ban ATCL - Airline E-1 - form tiếng ồn | P7: 1 | Q7: 1 | R7: 2 | S7: Yes | T7: Airline E-1-C4 Airline E-1-C14 Airline E-1-C13 | U7: 1. C4 2. C14 3. C13 | W7: Nhập thủ công | X7: - Năm | Y7: No
A8: =ROW()-2 -> 6 | B8: Ban TT | D8: Phase 1 | E8: Airline F-1 | F8: Social | G8: People and Development | H8: Tham gia hoạt động tình nguyện | I8: Volunteering during working hours | K8: Volunteering during working hours | M8: Dashboard | N8: Excel | O8: Airline F-1 - Volunteering during working hours (Scope: Corporate Communications Department) - Tham gia hoạt động tình nguyện (Phạm vi hiện tại: Ban Truyền thông) | P8: 1 | Q8: 1 | R8: 2 | S8: No | U8: 2. C14 | Y8: No
A9: =ROW()-2 -> 7 | B9: TCNL | D9: Phase 1 | E9: Airline F-2 | F9: Social | G9: People and Development | H9: Mức độ hài lòng của nhân viên | I9: Employee satisfaction | K9: Employee satisfaction | M9: Dashboard | N9: Excel | O9: Airline F-2 - Employee satisfaction - Mức độ hài lòng của nhân viên | P9: 1 | Q9: 1 | R9: 1 | S9: No | T9: Airline F-2 | U9: 3. C13 | Y9: No
A10: =ROW()-2 -> 8 | B10: Ban ATCL | D10: Phase 2 | E10: Airlines C-1 | F10: Environment | G10: Energy and Emissions | K10: Significant spills | T10: Airlines C-1
A11: =ROW()-2 -> 9 | B11: TCNL | D11: Phase 1 | E11: GRI 201-3 | F11: Social | G11: Labor Conditions | J11: Cam kết chi trả lương hưu và phúc lợi | K11: Defined benefit plan obligations and other retirement plans | M11: Text only (báo cáo tĩnh) | T11: GRI 201-3
A12: =ROW()-2 -> 10 | B12: Tổ Thư ký | D12: Phase 1 | E12: GRI 201-4 | F12: Governance | G12: Conduct and Compliance | J12: Trợ cấp/tài trợ nhận từ chính phủ | K12: Financial assistance received from government | L12: =VLOOKUP(#REF!,'29 Chỉ tiêu Text'!$C$2:$F$30,4,0) -> #REF! | M12: Text only (báo cáo tĩnh) | T12: GRI 201-4
A13: =ROW()-2 -> 11 | B13: TCNL | D13: Phase 1 | E13: GRI 202-1 | F13: Social | G13: Labor Conditions | H13: Tỷ lệ lương khởi điểm so với lương tối thiểu vùng 1 | I13: Ratios of standard entry-level wage by gender compared to local minimum wage | K13: Ratios of standard entry-level wage by gender compared to local minimum wage | M13: Dashboard | N13: Excel | O13: GRI 202-1 - Ratios of standard entry level wage by gender compared to local minimum wage - Tỷ lệ lương khởi điểm so với lương tối thiểu vùng 1 | P13: 1 | Q13: 1 | R13: 1 | S13: Yes | T13: GRI 202-1-01 GRI 202-1-02 GRI 202-1-03 | U13: 1. Tỷ lệ lương khởi điểm phi công Việt Nam so với lương tối thiểu vùng 2. Tỷ lệ lương khởi điểm tiếp viên cơ hữu so với lương tối thiểu vùng 3. Tỷ lệ lương khởi điểm lao động mặt đất so với lương tối thiểu vùng | V13: ≥ KH | W13: Nhập thủ công | X13: - Năm | Y13: No
A14: =ROW()-2 -> 12 | B14: TCNL | D14: Phase 1 | E14: GRI 202-2 | F14: Social | G14: Labor Conditions | H14: Tỷ lệ lãnh đạo cấp cao là người bản địa | I14: Proportion of senior management hired from the local community | K14: Proportion of senior management hired from the local community | M14: Dashboard | N14: Excel | O14: GRI 202-2 - Tỷ lệ lãnh đạo cấp cao là người bản địa | P14: 1 | Q14: 1 | R14: 1 | S14: Yes | T14: GRI 202-2 | U14: Tỷ lệ lãnh đạo cấp cao là người Việt Nam tại Việt Nam | V14: = KH | W14: Nhập thủ công | X14: - Năm | Y14: No
A15: =ROW()-2 -> 13 | B15: Tổ Thư ký | D15: Phase 1 | E15: GRI 204-1 | F15: Social | G15: Supply Chain Sustainability | K15: Proportion of spending on local suppliers | N15: CMS | Q15: N/A | R15: 2 | S15: No | T15: GRI 204-1 | Y15: No
A16: =ROW()-2 -> 14 | B16: Tổ Thư ký | D16: Phase 1 | E16: GRI 205-2 | F16: Governance | G16: Conduct and Compliance | J16: Truyền thông, đào tạo về chống tham nhũng | K16: Communication and training about anti-corruption policies and procedures | L16: =VLOOKUP(#REF!,'29 Chỉ tiêu Text'!$C$2:$F$30,4,0) -> #REF! | M16: Text only (báo cáo tĩnh) | T16: GRI 205-2
A17: =ROW()-2 -> 15 | B17: Tổ Thư ký | D17: Phase 1 | E17: GRI 205-3 | F17: Governance | G17: Conduct and Compliance | J17: Sự cố tham nhũng xác nhận và biện pháp xử lý | K17: Confirmed incidents of corruption and actions taken | L17: =VLOOKUP(#REF!,'29 Chỉ tiêu Text'!$C$2:$F$30,4,0) -> #REF! | M17: Text only (báo cáo tĩnh) | T17: GRI 205-3
A18: =ROW()-2 -> 16 | B18: Tổ Thư ký | D18: Phase 1 | E18: GRI 206-1 | F18: Governance | G18: Conduct and Compliance | J18: Vụ kiện về cạnh tranh không lành mạnh, độc quyền | K18: Legal actions for anti-competitive behavior, anti-trust, and monopoly practices | L18: =VLOOKUP(#REF!,'29 Chỉ tiêu Text'!$C$2:$F$30,4,0) -> #REF! | M18: Text only (báo cáo tĩnh) | T18: GRI 206-1
A19: =ROW()-2 -> 17 | B19: Tổ Thư ký | D19: Phase 1 | E19: GRI 2-10 | F19: Governance | G19: Conduct and Compliance | J19: Quy trình đề cử, lựa chọn cơ quan quản lý cao nhất | K19: Nomination and selection of the highest governance body | L19: =VLOOKUP(#REF!,'29 Chỉ tiêu Text'!$C$2:$F$30,4,0) -> #REF! | M19: Text only (báo cáo tĩnh) | T19: GRI 2-10
A20: =ROW()-2 -> 18 | B20: Tổ Thư ký | D20: Phase 1 | E20: GRI 2-11 | F20: Governance | G20: Conduct and Compliance | J20: Chủ tịch HĐQT | K20: Chair of the highest governance body | L20: =VLOOKUP(#REF!,'29 Chỉ tiêu Text'!$C$2:$F$30,4,0) -> #REF! | M20: Text only (báo cáo tĩnh) | T20: GRI 2-11
A21: =ROW()-2 -> 19 | B21: Tổ Thư ký | D21: Phase 1 | E21: GRI 2-12 | F21: Governance | G21: Conduct and Compliance | J21: Vai trò của HĐQT trong giám sát quản lý tác động | K21: Role of the highest governance body in overseeing the management of impacts | L21: =VLOOKUP(#REF!,'29 Chỉ tiêu Text'!$C$2:$F$30,4,0) -> #REF! | M21: Text only (báo cáo tĩnh) | T21: GRI 2-12
A22: =ROW()-2 -> 20 | B22: Tổ Thư ký | D22: Phase 1 | E22: GRI 2-13 | F22: Governance | G22: Conduct and Compliance | J22: Ủy quyền trách nhiệm quản lý các tác động | K22: Delegating authority | L22: =VLOOKUP(#REF!,'29 Chỉ tiêu Text'!$C$2:$F$30,4,0) -> #REF! | M22: Text only (báo cáo tĩnh) | T22: GRI 2-13
A23: =ROW()-2 -> 21 | B23: Tổ Thư ký | D23: Phase 1 | E23: GRI 2-14 | F23: Governance | J23: Vai trò của cơ quan quản trị cao nhất trong báo cáo bền vững | L23: =VLOOKUP(#REF!,'29 Chỉ tiêu Text'!$C$2:$F$30,4,0) -> #REF!
A24: =ROW()-2 -> 22 | B24: Tổ Thư ký | D24: Phase 1 | E24: GRI 2-15 | F24: Governance | G24: Conduct and Compliance | J24: Xung đột lợi ích | K24: Conflicts of interest | L24: =VLOOKUP(#REF!,'29 Chỉ tiêu Text'!$C$2:$F$30,4,0) -> #REF! | M24: Text only (báo cáo tĩnh) | T24: GRI 2-15
A25: =ROW()-2 -> 23 | B25: Tổ Thư ký | D25: Phase 1 | E25: GRI 2-16 | F25: Governance | J25: Báo cáo các mối quan ngại nghiêm trọng | L25: =VLOOKUP(#REF!,'29 Chỉ tiêu Text'!$C$2:$F$30,4,0) -> #REF!
A26: =ROW()-2 -> 24 | B26: Tổ Thư ký | D26: Phase 1 | E26: GRI 2-17 | F26: Governance | J26: Kiến thức tập thể của cơ quan quản lý cao nhất | L26: =VLOOKUP(#REF!,'29 Chỉ tiêu Text'!$C$2:$F$30,4,0) -> #REF!
A27: =ROW()-2 -> 25 | B27: Tổ Thư ký | D27: Phase 1 | E27: GRI 2-18 | F27: Governance | J27: Đánh giá hiệu quả hoạt động của cơ quan quản trị cao nhất | L27: =VLOOKUP(#REF!,'29 Chỉ tiêu Text'!$C$2:$F$30,4,0) -> #REF!
A28: =ROW()-2 -> 26 | B28: TCNL | D28: Phase 2 | E28: GRI 2-21 | F28: Social | G28: Labor Conditions | K28: Annual total compensation ratio | T28: GRI 2-21
A29: =ROW()-2 -> 27 | B29: Tổ Thư ký | D29: Phase 1 | E29: GRI 2-23 | F29: Governance | G29: Conduct and Compliance | J29: Các cam kết về chính sách | K29: Policy commitments | L29: =VLOOKUP(#REF!,'29 Chỉ tiêu Text'!$C$2:$F$30,4,0) -> #REF! | M29: Text only (báo cáo tĩnh) | T29: GRI 2-23
A30: =ROW()-2 -> 28 | B30: Tổ Thư ký | D30: Phase 1 | E30: GRI 2-24 | F30: Governance | J30: Lồng ghép các cam kết chính sách | L30: =VLOOKUP(#REF!,'29 Chỉ tiêu Text'!$C$2:$F$30,4,0) -> #REF!
A31: =ROW()-2 -> 29 | B31: Tổ Thư ký | D31: Phase 1 | E31: GRI 2-25 | F31: Governance | J31: Quy trình khắc phục các tác động tiêu cực | L31: =VLOOKUP(#REF!,'29 Chỉ tiêu Text'!$C$2:$F$30,4,0) -> #REF!
A32: =ROW()-2 -> 30 | B32: Tổ Thư ký | D32: Phase 1 | E32: GRI 2-26 | F32: Governance | G32: Conduct and Compliance | J32: Cơ chế tham vấn, phản ánh các vấn đề đạo đức | K32: Mechanisms for seeking advice and raising concerns about ethics | L32: =VLOOKUP(#REF!,'29 Chỉ tiêu Text'!$C$2:$F$30,4,0) -> #REF! | M32: Text only (báo cáo tĩnh) | T32: GRI 2-26
A33: =ROW()-2 -> 31 | B33: Tổ Thư ký | D33: Phase 1 | E33: GRI 2-27 | F33: Governance | J33: Tuân thủ pháp luật và các quy định | L33: =VLOOKUP(#REF!,'29 Chỉ tiêu Text'!$C$2:$F$30,4,0) -> #REF!
A34: =ROW()-2 -> 32 | B34: Tổ Thư ký | D34: Phase 1 | E34: GRI 2-29 | F34: Governance | G34: Conduct and Compliance | J34: Tiếp cận đối thoại các bên liên quan | K34: Approach to stakeholder engagement | L34: =VLOOKUP(#REF!,'29 Chỉ tiêu Text'!$C$2:$F$30,4,0) -> #REF! | M34: Text only (báo cáo tĩnh) | T34: GRI 2-29
A35: =ROW()-2 -> 33 | B35: TCNL | D35: Phase 1 | E35: GRI 2-30 | F35: Social | G35: Labor Conditions | J35: Thỏa ước lao động tập thể | K35: Collective bargaining agreements | M35: Text only (báo cáo tĩnh) | T35: GRI 2-30
A36: =ROW()-2 -> 34 | B36: TCNL | D36: Phase 2 | E36: GRI 2-6 | F36: Social | G36: Labor Conditions | K36: Activities, value chain and other business relationships | T36: GRI 2-6
A37: =ROW()-2 -> 35 | B37: Tổ dịch vụ | D37: Phase 2 | E37: GRI 2-6 | F37: Social | G37: Supply Chain Sustainability | K37: Activities, value chain and other business relationships | T37: GRI 2-6
A38: =ROW()-2 -> 36 | B38: TCNL | D38: Phase 1 | E38: GRI 2-7 | F38: Social | G38: Labor Conditions | H38: Quy mô tổ chức | I38: Scale of the organization | K38: Scale of the organization | M38: Dashboard | N38: Skyhr | Q38: N/A | R38: 2 | S38: Yes | T38: GRI 2-7-01 GRI 2-7-02 | U38: 1. Lao động 31/12 - Number of employees as of December 31 2. Lao động sử dụng bình quân năm - Average Employee | V38: ≥ KH | W38: Nhập thủ công | X38: - Năm | Y38: No
A39: =ROW()-2 -> 37 | B39: Tổ Thư ký | D39: Phase 1 | E39: GRI 2-9 | F39: Governance | G39: Conduct and Compliance | J39: Cơ cấu và thành phần quản trị | K39: Governance structure and composition | L39: =VLOOKUP(#REF!,'29 Chỉ tiêu Text'!$C$2:$F$30,4,0) -> #REF! | M39: Text only (báo cáo tĩnh) | T39: GRI 2-9
A40: =ROW()-2 -> 38 | B40: Tổ dịch vụ | D40: Phase 2 | E40: GRI 301-1 | F40: Environment | G40: Waste and Effluents | K40: Materials used by weight or volume | T40: GRI 301-1
...

Sheet 29 Chỉ tiêu Text
A1: TT | B1: Trụ cột | C1: Mã GRI | D1: Chỉ tiêu (Eng) | E1: Chỉ tiêu (Vie) | F1: Yêu cầu của GRI | G1: Câu hỏi | H1: Hiện trạng | I1: PIC | J1: Nội dung hiển thị cho VNA
A2: 1 | B2: Xã hội | C2: GRI 401-2 | D2: Benefits provided to full-time employees that are not provided to temporary or part-time employees | E2: Phúc lợi cho nhân viên toàn thời gian | F2: 1. Các phúc lợi tiêu chuẩn được cung cấp cho nhân viên làm việc toàn thời gian của tổ chức 2. Danh sách các phúc lợi này bao gồm: (i) Bảo hiểm nhân thọ (Life insurance). (ii) Chăm sóc sức khỏe y tế (Health care). (iii) Bảo hiểm thương tật và mất khả năng lao động (Disability and invalidity coverage). (iv) Chế độ nghỉ phép chăm con/thai sản (Parental leave). (v) Chế độ hưu trí (Retirement provision). (vi) Quyền sở hữu cổ phần (Stock ownership). (vii) Các phúc lợi khác. | G2: Tổng công ty đã có những chính sách đãi ngộ như thế nào đối với người lao động? | H2: Đáp ứng | I2: Ban TCNL | J2: Mọi nhân viên chính thức ký hợp đồng lao động trực tiếp với Vietnam Airlines đều được hưởng chế độ đãi ngộ toàn diện, vượt trội so với mặt bằng chung của thị trường lao động, bao gồm: Bảo hiểm sức khỏe, Bảo hiểm hưu trí tự nguyện nhóm, vé máy bay giảm cước trên các chặng bay của Vietnam Airlines và đối tác liên kết (vé ID/AD, my ID Travel); các chính sách nhân văn, gắn kết như hỗ trợ các gia đình thương binh liệt sỹ, quà sinh nhật người lao động, quà tặng 8/3, 20/10 dành cho lao động nữ, …
A3: 2 | B3: Xã hội | C3: GRI 403-4 | D3: Worker participation, consultation, and communication on occupational health and safety | E3: Các chương trình NLĐ tham gia, đóng góp ý kiến và trao đổi về các chính sách sức khỏe và an toàn nghề nghiệp | F3: 1. Quy trình tổ chức cho người lao động tham gia và tham vấn vào việc xây dựng, triển khai, cũng như đánh giá hệ thống quản lý an toàn và sức khỏe nghề nghiệp. 2. Cách thức tổ chức cung cấp quyền truy cập và truyền đạt các thông tin liên quan về an toàn, sức khỏe nghề nghiệp đến người lao động. 3. Thông tin chi tiết về các Ủy ban an toàn và sức khỏe chung (các ủy ban chính thức kết hợp giữa đại diện ban quản lý và người lao động) - nếu có tồn tại, dựa trên 4 tiêu chí bắt buộc: (i) Trách nhiệm của ủy ban; (ii) Tần suất tổ chức họp; (iii) Thẩm quyền ra quyết định của ủy ban; (iv) Tình trạng đại diện của người lao động (phải xác định rõ có nhóm lao động nào không được đại diện trong các ủy ban này không, và giải thích lý do tại sao). | G3: Tổng công ty có duy trì các kênh đối thoại và cơ chế đại diện cho người lao động trong công tác quản lý an toàn và sức khỏe nghề nghiệp không? | H3: Đáp ứng | I3: Ban TCNL | J3: Vietnam Airlines duy trì cơ chế đối thoại dân chủ trong công tác ATVSLĐ. Hội đồng ATVSLĐ của TCT được thành lập với 6 thành viên, trong đó đại diện người sử dụng lao động làm Chủ tịch; đại diện công đoàn Công đoàn TCT làm Phó Chủ tịch; đại diện Ban Tổ chức và nhân lực làm Ủy viên thường trực-Thư ký và các thành viên thuộc các ban An toàn chất lượng, An ninh Hàng không và Trạm y tế thuộc Đoàn bay 919. Hội đồng có nhiệm vụ tư vấn, phối hợp với người sử dụng lao động xây dựng nội quy, quy trình, kế hoạch và biện pháp ATVSLĐ; tổ chức đối thoại hằng năm giữa người lao động và người sử dụng lao động nhằm chia sẻ thông tin, tăng cường sự hiểu biết và thúc đẩy cải thiện các điều kiện làm việc công bằng, an toàn cho người lao động; nâng cao hiệu quả thực hiện chính sách, pháp luật về ATVSLĐ tại nơi làm việc; kiểm tra tình hình thực hiện tác ATVSLĐ; và yêu cầu người sử dụng lao động xử lý, khắc phục nguy cơ mất ATVSLĐ. Bên cạnh đó, kế hoạch ATVSLĐ hằng năm của các cơ quan, đơn vị trong TCT đều xây dựng nội dung “Thông tin, tuyên truyền, giáo dục về ATVSLĐ
A4: 3 | B4: Xã hội | C4: GRI 403-10 | D4: Work-related ill health | E4: Sự cố phân biệt đối xử và biện pháp xử lý | F4: 1. Số liệu thống kê về bệnh nghề nghiệp, được báo cáo tách biệt cho 2 nhóm: (a) Nhân viên của tổ chức (Employees) và (b) Người lao động không phải nhân viên nhưng công việc hoặc nơi làm việc do tổ chức kiểm soát. Dữ liệu mỗi nhóm phải bao gồm 3 chỉ tiêu: (i) Số ca tử vong do bệnh nghề nghiệp; (ii) Số ca mắc bệnh nghề nghiệp / suy giảm sức khỏe liên quan đến công việc có thể ghi nhận được (recordable cases); (iii) Các loại bệnh nghề nghiệp / suy giảm sức khỏe chính. 2. Thông tin phân tích về các mối nguy hiểm liên quan đến công việc (work-related hazards) có nguy cơ gây bệnh, dựa trên 3 tiêu chí: (i) Cách thức tổ chức xác định các mối nguy hiểm này; (ii) Các mối nguy hiểm cụ thể đã gây ra hoặc góp phần gây ra các ca bệnh trong kỳ báo cáo; (iii) Các hành động đã hoặc đang được thực hiện nhằm loại trừ mối nguy hiểm và giảm thiểu rủi ro. | G4: Tổng công ty đã kiểm soát và ghi nhận số liệu về bệnh nghề nghiệp đối với toàn bộ nhân viên như thế nào? | H4: Đáp ứng | I4: Ban TCNL | J4: Vietnam Airlines đặt sức khỏe thể chất và tinh thần của người lao động là ưu tiên hàng đầu trong quản trị ATVSLĐ. Trong kỳ báo cáo, TCT tiếp tục duy trì thành tích xuất sắc với 0 ca bệnh nghề nghiệp mới phát sinh. Để bảo đảm sức khỏe khai thác cho tổ bay, hãng tuân thủ tuyệt đối quy trình quản trị mệt mỏi phi hành đoàn (FRMS), bảo đảm 100% số giờ nghỉ ngơi tối thiểu giữa các ca bay đạt chuẩn an toàn. Đồng thời, định kỳ hàng năm TCT tổ chức khám sức khỏe cho toàn thể người lao động ít nhất 1 lần/ năm, một số lao động đặc thù được khám 2 lần/ năm hoặc khám bệnh nghề nghiệp chuyên sâu tại các cơ sở y tế đạt chuẩn, chi phí do TCT chi trả.
A5: 4 | B5: Xã hội | C5: GRI 406-1 | D5: Incidents of discrimination and corrective actions taken | E5: Sự cố phân biệt đối xử và biện pháp xử lý (Phần nhân sự) | F5: 1. Tổng số vụ việc phân biệt đối xử đã xảy ra và được ghi nhận trong kỳ báo cáo. 2. Tình trạng của các vụ việc và các hành động khắc phục tương ứng, được phân loại cụ thể theo 4 trạng thái bắt buộc: (i) Vụ việc đã được tổ chức tiếp nhận và đang xem xét/điều tra; (ii) Kế hoạch khắc phục (remediation plans) đang trong quá trình triển khai thực hiện; (iii) Kế hoạch khắc phục đã được triển khai hoàn tất (kèm theo kết quả đã được đánh giá thông qua các quy trình kiểm tra quản lý nội bộ định kỳ); (iv) Vụ việc đã khép lại và không còn thuộc diện phải tiếp tục xử lý hoặc hành động thêm. | G5: Tổng công ty có đảm bảo môi trường làm việc không xảy ra các hành vi kỳ thị hay phân biệt đối xử đối với người lao động không? | H5: Đáp ứng | I5: Ban TCNL | J5: Trong kỳ báo cáo, TCT ghi nhận 0 ý kiến về phân biệt đối xử hay kỳ thị đối với nhân viên nội bộ. TCT duy trì nguyên tắc bình đẳng, không chấp nhận hành vi xúc phạm, đe dọa hoặc phân biệt đối xử trong môi trường làm việc.
A6: 5 | B6: Xã hội | C6: GRI 2-30 | D6: Collective bargaining agreements | E6: Thỏa ước lao động tập thể | F6: 1. Tỷ lệ phần trăm (%) tổng số nhân viên của tổ chức được điều chỉnh/bảo vệ bởi các thỏa ước lao động tập thể. (2) Cung cấp thông tin đối với những nhân viên không được điều chỉnh bởi các thỏa ước lao động tập thể. Cụ thể, tổ chức phải báo cáo rõ liệu các điều kiện làm việc và điều khoản sử dụng lao động của nhóm nhân viên này có được xác định dựa trên: (i) Các thỏa ước lao động tập thể đang được áp dụng cho các nhân viên khác trong cùng tổ chức hay không; hoặc (ii) Các thỏa ước lao động tập thể từ các tổ chức khác hay không. | G6: Các chế độ đãi ngộ dành cho người lao động có được áp dụng dựa trên cơ sở pháp lý và thỏa ước tương đương nào để bảo đảm tối đa quyền lợi? | H6: Đáp ứng | I6: Ban TCNL | J6: Vietnam Airlines tôn trọng, cam kết bảo vệ quyền và lợi ích hợp pháp của người lao động thông qua cơ chế đối thoại, thương lượng và thỏa thuận. 100% người lao động được bảo vệ quyền lợi tại Thỏa ước lao động tập thể. Hằng năm, Ban lãnh đạo TCT phối hợp chặt chẽ với Ban chấp hành Công đoàn TCT tổ chức Hội nghị người lao động và đối thoại định kỳ nhằm lắng nghe tâm tư, nguyện vọng và liên tục cải thiện điều kiện làm việc, quyền và lợi ích hợp pháp của người lao động.
A7: 6 | B7: Xã hội | C7: GRI 404-3 | D7: Percentage of employees receiving regular performance and career development reviews | F7: 1. Tỷ lệ phần trăm (%) tổng số nhân viên được đánh giá hiệu quả công việc và phát triển nghề nghiệp định kỳ trong kỳ báo cáo. 2. Dữ liệu về tỷ lệ phần trăm này phải được báo cáo phân loại chi tiết theo 2 tiêu chí: (i) Giới tính; (ii) Cấp bậc nhân viên. | G7: Tổng công ty đã triển khai quy trình đánh giá kết quả công việc và lộ trình phát triển nghề nghiệp định kỳ cho các nhóm nhân viên chưa? | H7: Đáp ứng | I7: Ban TCNL | J7: Vietnam Airlines cam kết xây dựng một môi trường làm việc công bằng và tạo động lực phát triển liên tục thông qua hệ thống đánh giá kết quả công việc được số hóa trên nền tảng SkyHR. Hàng tháng, công tác đánh giá hiệu quả công việc được thực hiện một cách khách quan, công khai và minh bạch, áp dụng đồng bộ hệ thống Thẻ điểm cân bằng (BSC) kết hợp với các chỉ số đo lường hiệu quả cốt lõi (KPI) và các trục chỉ số đánh giá theo mô hình quản trị hiện đại. Kết quả đánh giá thực hiện công việc này là căn cứ quan trọng để Tổng công ty thực thi các chính sách nhân sự bền vững, bao gồm: quy hoạch, bổ nhiệm, điều động, luân chuyển; xác định nhu cầu đào tạo, bồi dưỡng phát triển năng lực; xét nâng bậc, khen thưởng, kỷ luật và giải quyết các quan hệ lao động phát sinh.
A8: 7 | B8: Xã hội | C8: GRI 201-3 | D8: Defined benefit plan obligations and other retirement plans | E8: Cam kết chi trả lương hưu và phúc lợi | F8: 1. Nếu các nghĩa vụ của chương trình hưu trí được chi trả bằng nguồn tài chính chung của tổ chức, phải báo cáo giá trị ước tính của các khoản nghĩa vụ này. 2. Nếu có một quỹ riêng biệt được thiết lập để chi trả các khoản nghĩa vụ lương hưu của chương trình, cần báo cáo 3 thông tin: (i) Mức độ (tỷ lệ) mà các nghĩa vụ của quỹ được ước tính sẽ được đảm bảo chi trả bởi các tài sản đã được trích lập; (ii) Cơ sở phương pháp luận để đưa ra mức ước tính đó; (iii) Thời điểm thực hiện việc ước tính. | G8: Tổng công ty có thực hiện đầy đủ các khoản bảo hiểm, mức trích đóng cụ thể ra sao? | H8: Đáp ứng | I8: Ban TCNL | J8: Vietnam Airlines thực hiện đóng đầy đủ, đúng hạn các khoản bảo hiểm bắt buộc theo đúng các quy định của Nhà nước. Ngoài ra, để bảo đảm an sinh xã hội dài hạn và bổ sung, hỗ trợ tài chính/ thu nhập sau khi nghỉ hưu cho người lao động, tùy thuộc vào kết quả sản xuất kinh doanh hằng năm, TCT thực hiện đóng vào quỹ hưu trí tự nguyện nhóm. Tổng số tiền đóng tối đa 300 triệu VND/người lao động/hợp đồng, giúp người lao động hoàn toàn yên tâm đồng hành dài hạn cùng sự phát triển của hãng hàng không quốc gia."
A9: 8 | B9: Quản trị | C9: GRI 2-9 | D9: =VLOOKUP(C9,'95 Chỉ tiêu'!$B$4:$K$98,5,0) -> #N/A | E9: Cơ cấu và thành phần quản trị | F9: 1. Sơ đồ cơ cấu quản trị 2. Danh sách các Ủy ban thuộc HĐQT. 3. Bảng thành phần HĐQT và từng Ủy ban theo 8 tiêu chí bắt buộc của GRI: (i) thành viên điều hành / không điều hành; (ii) tính độc lập; (iii) nhiệm kỳ / thời gian đã tại vị; (iv) số vị trí kiêm nhiệm quan trọng khác và tính chất của việc kiêm nhiệm; (v) giới tính; (vi) nhóm xã hội yếu thế/ít được đại diện; (vii) năng lực liên quan đến tác động tới TCT; (viii) đại diện của các bên liên quan. | H9: Đáp ứng | I9: Tổ Thư ký | J9: Cơ cấu quản trị của Vietnam Airlines gồm ĐHĐCĐ, HĐQT, Ban Kiểm soát và TGĐ cùng bộ máy điều hành. HĐQT thành lập 02 tiểu ban: Tiểu ban Chiến lược và đầu tư; Tiểu ban Lao động và Tiền lương Thành phần Hội đồng quản trị: 07 thành viên, gồm 01 thành viên độc lập, thành viên người đại diện phần vốn nhà nước và đại diện ANA. Đối với PTBV, HĐQT giữ vai trò định hướng và giám sát cao nhất. BĐH Chương trình PTBV do TGĐ làm Trưởng ban là cơ quan chịu trách nhiệm ra quyết định và giám sát việc quản lý các tác động kinh tế, môi trường và con người; TTK là cơ quan thường trực điều phối chuyên môn; các Tổ công tác được thành lập theo từng lĩnh vực/chương trình để chủ trì triển khai. (vẽ sơ đồ tương tự báo cáo thường niên)
A10: 9 | B10: Quản trị | C10: GRI 2-10 | D10: =VLOOKUP(C10,'95 Chỉ tiêu'!$B$4:$K$98,5,0) -> #N/A | E10: Quy trình đề cử, lựa chọn cơ quan quản lý cao nhất | F10: 1. Quy trình đề cử, lựa chọn thành viên HĐQT và các tiểu ban 2. Tiêu chí lựa chọn — bắt buộc nêu rõ có xét đến và xét như thế nào đối với: (i) ý kiến của các bên liên quan (bao gồm cổ đông); (ii) tính đa dạng; (iii) tính độc lập; (iv) năng lực liên quan đến tác động PTBV của TCT. | H10: Đáp ứng | I10: Tổ Thư ký | J10: Thành viên HĐQT Vietnam Airlines do ĐHĐCĐ bầu theo phương thức bầu dồn phiếu. Quyền đề cử ứng viên được thực hiện theo tỷ lệ sở hữu cổ phần; Với tư cách doanh nghiệp có vốn nhà nước chi phối, việc giới thiệu người đại diện phần vốn nhà nước tham gia HĐQT được thực hiện theo quy định của Luật số 68/2025/QH15 và chỉ đạo của cơ quan đại diện chủ sở hữu. Trong quá trình đề cử và lựa chọn, TCT xem xét: ý kiến của cổ đông và các bên liên quan thông qua ĐHĐCĐ; tính độc lập của thành viên theo quy định pháp luật về công ty đại chúng; và năng lực, kinh nghiệm phù hợp với đặc thù ngành hàng không.
A11: 10 | B11: Quản trị | C11: GRI 2-11 | D11: =VLOOKUP(C11,'95 Chỉ tiêu'!$B$4:$K$98,5,0) -> #N/A | E11: Chủ tịch HĐQT | F11: Nêu rõ: Chủ tịch HĐQT có đồng thời là cán bộ điều hành cấp cao của TCT hay không. Nếu Chủ tịch kiêm nhiệm điều hành: phải mô tả chức năng điều hành, lý do bố trí và cách ngăn ngừa/giảm thiểu xung đột lợi ích. | H11: Đáp ứng | I11: Tổ Thư ký | J11: CT HĐQT Vietnam Airlines là ông Đặng Ngọc Hòa. CT HĐQT không đồng thời là cán bộ điều hành cấp cao của TCT: chức danh TGĐ - người đại diện theo pháp luật và điều hành hoạt động hằng ngày - do ông Lê Hồng Hà đảm nhiệm.
A12: 11 | B12: Quản trị | C12: GRI 2-12 | D12: =VLOOKUP(C12,'95 Chỉ tiêu'!$B$4:$K$98,5,0) -> #N/A | E12: Vai trò của HĐQT trong giám sát quản lý tác động | F12: 1. Vai trò của HĐQT và của cán bộ điều hành cấp cao trong việc xây dựng, phê duyệt và cập nhật: tầm nhìn/sứ mệnh/giá trị cốt lõi; chiến lược PTBV; các chính sách và mục tiêu PTBV. 2. Vai trò của HĐQT trong giám sát quy trình thẩm định chi tiết và các quy trình khác nhằm nhận diện và quản lý tác động kinh tế – môi trường – con người, gồm: (i) HĐQT có và tương tác với các bên liên quan như thế nào để hỗ trợ các quy trình này; (ii) HĐQT xem xét, sử dụng kết quả đầu ra của các quy trình này ra sao. 3. Vai trò của HĐQT trong rà soát tính hiệu quả của các quy trình nêu trên và tần suất rà soát. | H12: Đáp ứng | I12: Tổ Thư ký | J12: HĐQT là cơ quan quản lý cao nhất của Vietnam Airlines giữ vai trò định hướng và giám sát toàn diện đối với phát triển bền vững. TGĐ và BĐH Chương trình PTBV chịu trách nhiệm xây dựng, đề xuất và cập nhật các nội dung về tầm nhìn, sứ mệnh, giá trị cốt lõi, chiến lược PTBV để trình HĐQT. HĐQT giám sát các quy trình nhận diện, đánh giá và quản lý tác động kinh tế, môi trường và con người thông qua báo cáo của BĐH Chương trình PTBV. Rà soát hiệu quả: TTK họp hàng tháng, BĐH họp hàng quý, rà soát các chỉ tiêu PTBV và có báo cáo lên HĐQT nếu cần
A13: 12 | B13: Quản trị | C13: GRI 2-13 | D13: =VLOOKUP(C13,'95 Chỉ tiêu'!$B$4:$K$98,5,0) -> #N/A | E13: Ủy quyền trách nhiệm quản lý các tác động | F13: 1. Cách HĐQT phân cấp trách nhiệm quản lý tác động, gồm: (i) HĐQT có bổ nhiệm cán bộ điều hành cấp cao chịu trách nhiệm về quản lý tác động hay không; (ii) trách nhiệm có được giao tiếp cho người lao động khác hay không. 2. Quy trình báo cáo ngược lên HĐQT về việc quản lý tác động. | H13: Đáp ứng | I13: Tổ Thư ký | J13: Hội đồng quản trị phân cấp trách nhiệm quản lý các tác động kinh tế, môi trường và con người cho Tổng giám đốc và bộ máy điều hành. BĐH Chương trình PTBV do TGĐ làm Trưởng ban là đầu mối cấp cao nhất chịu trách nhiệm điều hành công tác PTBV của TCT. TTK là cơ quan thường trực, điều phối chuyên môn và tham mưu tổng hợp, chịu sự chỉ đạo trực tiếp của Trưởng BĐH và PTBTT. Các Tổ công tác được thành lập theo từng lĩnh vực để chủ trì triển khai và chịu trách nhiệm về kết quả trong phạm vi được giao. Ở cấp thực thi, trách nhiệm được giao tiếp cho các Ban chức năng và đơn vị theo lĩnh vực chuyên môn: kiểm kê và giảm phát thải, quản lý nhiên liệu, mua sắm, nhân sự, dịch vụ hành khách, an toàn – chất lượng. Cơ chế báo cáo ngược: BĐH Chương trình Phát triển bền vững tổng hợp và báo cáo HĐQT về tiến độ, kết quả và các vấn đề phát sinh trong quản lý tác động PTBV.
A14: 13 | B14: Quản trị | C14: GRI 2-14 | E14: Vai trò của cơ quan quản trị cao nhất trong báo cáo bền vững | F14: Cần chỉ rõ: HĐQT có chịu trách nhiệm rà soát và phê duyệt thông tin công bố trong Báo cáo PTBV, bao gồm danh mục các chủ đề trọng yếu, hay không. Nếu có, hãy mô tả quy trình. Nếu không, hãy đưa lý do. | H14: Đáp ứng | I14: Tổ Thư ký | J14: HĐQT chịu trách nhiệm rà soát và phê duyệt các thông tin công bố trong Báo cáo thường niên, bao gồm nội dung báo cáo PTBV. Quy trình rà soát và phê duyệt: TTK BĐH Chương trình PTBV chủ trì thu thập dữ liệu từ các Tổ công tác, CQĐV, tổng hợp và xây dựng dự thảo báo cáo, gửi báo cáo cho Ban TT. Ban TT tập hợp thông tin báo cáo Ban Giám đốc và HĐQT báo cáo thường niên. HĐQT xem xét và phê duyệt trước khi công bố.
A15: 14 | B15: Quản trị | C15: GRI 2-15 | D15: =VLOOKUP(C15,'95 Chỉ tiêu'!$B$4:$K$98,5,0) -> #N/A | E15: Xung đột lợi ích | F15: Mô tả quy trình HĐQT ngăn ngừa và giảm thiểu xung đột lợi ích. Báo cáo nếu xung đột lợi ích được tiết lộ đến các bên liên quan, ít nhất là bao gồm: i. Kiêm nhiệm chéo trong HĐQT ii. Sở hữu chéo với nhà cung cấp và các bên liên quan iii. Sự tồn tại của cổ đông chi phối iv. Các bên liên quan: mối quan hệ, giao dịch và số dư còn lại. | H15: Đáp ứng | I15: Tổ Thư ký | J15: Điều 55 trong Điều lệ TCT ban hành ngày 28/6/2026 quy định về trách nhiệm trung thực và tránh các xung đột về quyền lợi. Xung đột lợi ích tới các bên liên quan: i. Kiêm nhiệm chéo: • Ông Đặng Ngọc Hòa: Ủy viên BCH Liên đoàn thương mại và công nghiệp Việt Nam (VCCI) • Ông Lê Hồng Hà: thành viên Hội đồng Học viện Hàng không Việt Nam nhiệm kỳ 2025-2030 • Ông Tạ Mạnh Hùng: Chủ tịch HĐTV Công ty TNHH MTV Dịch vụ mặt đất sân bay Việt Nam (VIAGS) • Ông Lê Trường Giang: Chủ tịch HĐQT Công ty cổ phần Dịch vụ hàng hóa Tân Sơn Nhất (TCS) • Ông Đinh Việt Tùng: PTGĐ TCT Đầu tư và Kinh doanh vốn nhà nước (SCIC). Chủ tịch HĐQT TCT Licogi. Chủ tịch HĐQT TCTCP Bảo Minh • Ông Trương Văn Phước: Ủy viên hội đồng khoa học của UB Thường vụ Quốc hội • Ông Hidekazu Isone: PTGĐ phụ trách chiến lược của ANA Holdings ii. Sở hữu chéo với nhà cung cấp: Vietnam Airlines nắm giữ vốn tại một số đơn vị đồng thời là nhà cung cấp dịch vụ cho Tổng công ty. iii. Cổ đông chi phối: Nhà nước là cổ đông chi phối, nắm giữ khoảng 86,42% vốn điều lệ thông qua Bộ Tài chính và Tổng công ty Đầu tư và Kinh doanh vốn nhà nước (SCIC). ANA Holdings là cổ đông chiến lược với tỷ lệ 5,62% iv. Giao dịch với bên liên quan: mối quan hệ, giá trị giao dịch và số dư còn lại với các bên liên quan được trình bày tại Thuyết minh Báo cáo tài chính hợp nhất đã kiểm toán hàng năm.
A16: 15 | B16: Quản trị | C16: GRI 2-16 | E16: Báo cáo các mối quan ngại nghiêm trọng | F16: 1. Mô tả "mối quan ngại nghiêm trọng" và việc các mối quan ngại nghiêm trọng được báo cáo lên HĐQT như thế nào 2. Tổng số và tính chất của các mối quan ngại nghiêm trọng đã được báo cáo lên HĐQT trong kỳ báo cáo. | H16: Đáp ứng | I16: Tổ Thư ký | J16: Vietnam Airlines xác định "mối quan ngại nghiêm trọng" là các vấn đề liên quan đến tác động tiêu cực tiềm ẩn hoặc thực tế đối với các bên liên quan, hoặc liên quan đến hành vi kinh doanh của Tổng công ty, có mức độ ảnh hưởng đủ lớn để cần đến sự xem xét của cơ quan quản trị cao nhất. Các mối quan ngại nghiêm trọng được truyền đạt lên Hội đồng quản trị thông qua hệ thống kiểm toán nội bộ. Ban Kiểm soát thực hiện chức năng giám sát độc lập và báo cáo ĐHĐCĐ. Các vấn đề phát sinh từ kênh tiếp nhận đơn thư khiếu nại, tố cáo, kiến nghị, phản ánh và từ cơ chế tố giác nội bộ được xử lý theo trình tự, thủ tục quy định và được báo cáo lên cấp có thẩm quyền tương ứng với tính chất, mức độ của vụ việc.
A17: 16 | B17: Quản trị | C17: GRI 2-17 | E17: Kiến thức tập thể của cơ quan quản lý cao nhất | F17: Các biện pháp đã thực hiện để nâng cao kiến thức, kỹ năng và kinh nghiệm tập thể của HĐQT về phát triển bền vững. | H17: Đáp ứng | I17: Tổ Thư ký | J17: Vietnam Airlines chú trọng nâng cao năng lực về PTBV cho đội ngũ quản trị và điều hành. Trong năm 2025, BĐH Chương trình PTBV đã hoàn thành chương trình đào tạo về PTBV do chuyên gia tư vấn độc lập bên ngoài thực hiện và dự định triển khai kế hoạch đối với HĐQT trong thời gian tới.
A18: 17 | B18: Quản trị | C18: GRI 2-18 | E18: Đánh giá hiệu quả hoạt động của cơ quan quản trị cao nhất | F18: 1. Mô tả quy trình đánh giá hiệu quả hoạt động của HĐQT trong việc giám sát quản lý tác động kinh tế – môi trường – con người 2. Đánh giá là độc lập hay tự đánh giá; tần suất đánh giá. 3. Các hành động đã thực hiện sau đánh giá, bao gồm thay đổi về thành phần HĐQT và thay đổi về thông lệ quản trị của tổ chức. | H18: Đáp ứng | I18: Tổ Thư ký | J18: Ban KS có đánh giá HĐQT hàng năm
A19: 18 | B19: Quản trị | C19: GRI 2-23 | D19: =VLOOKUP(C19,'95 Chỉ tiêu'!$B$4:$K$98,5,0) -> #N/A | E19: Các cam kết về chính sách | F19: 1. Danh mục các cam kết chính sách về ứng xử kinh doanh có trách nhiệm, bao gồm: i. các văn kiện liên chính phủ có thẩm quyền mà các cam kết đề cập đến; ii. cam kết có yêu cầu thực hiện thẩm định chi tiết hay không; iii. cam kết có áp dụng nguyên tắc phòng ngừa hay không; iv. cam kết có quy định về tôn trọng quyền con người hay không. 2. Cam kết riêng về tôn trọng quyền con người: i. các quyền con người được quốc tế công nhận mà cam kết này bao hàm; ii. các nhóm bên liên quan được đặc biệt quan tâm, gồm nhóm có nguy cơ/dễ bị tổn thương. 3. Đường dẫn công bố công khai của từng chính sách, hoặc lý do không công khai. 4. Cấp phê duyệt của từng chính sách - nêu rõ có phải cấp cao nhất hay không. 5. Phạm vi áp dụng. 6. Cách truyền thông cam kết tới người lao động, đối tác kinh doanh và các bên liên quan khác. | H19: Đáp ứng | I19: Tổ Thư ký | J19: Vietnam Airlines thiết lập hệ thống cam kết chính sách về ứng xử kinh doanh có trách nhiệm, được đăng tải trên các trang nội bộ của Vietnam Airlines, bao gồm: • Chương trình Phòng, chống tham nhũng, tiêu cực, thực hành tiết kiệm, chống lãng phí (ban hành năm 2025); • Bộ định nghĩa hành vi và Hướng dẫn thực hiện văn hóa chính trực • Chính sách An toàn (thuộc Tài liệu Hệ thống Quản lý An toàn – SMSM) • Quy chế quản lý lao động • Quy chế bảo vệ môi trường, sử dụng năng lượng tiết kiệm và hiệu quả • Quy chế đấu thầu và mua sắm • ...
A20: 19 | B20: Quản trị | C20: GRI 2-24 | E20: Lồng ghép các cam kết chính sách | F20: Mô tả cách VNA lồng ghép từng cam kết chính sách vào toàn bộ hoạt động và quan hệ kinh doanh, bao gồm: i. Cách phân bổ trách nhiệm thực thi cam kết theo các cấp trong tổ chức; ii. Cách tích hợp cam kết vào chiến lược, chính sách vận hành, quy trình vận hành; iii. Cách thực thi cam kết thông qua quan hệ kinh doanh; iv. Đào tạo về thực thi cam kết: đối tượng, nội dung, hình thức, tần suất, tỷ lệ hoàn thành. | H20: Đáp ứng | I20: Tổ Thư ký | J20: Vietnam Airlines lồng ghép các cam kết chính sách vào hoạt động, cụ thể: Phân bổ trách nhiệm theo cấp: HĐQT giữ vai trò giám sát cao nhất. TGĐ và BĐH Chương trình PTBV chịu trách nhiệm tổ chức thực hiện. Các Tổ công tác, CQĐV chịu trách nhiệm hằng ngày đối với từng nhóm cam kết theo lĩnh vực chuyên môn. Tích hợp vào chiến lược và quy trình vận hành: các cam kết phát triển bền vững được cụ thể hóa thành chỉ tiêu trong kế hoạch sản xuất kinh doanh hằng năm. Thực thi qua quan hệ kinh doanh: ví dụ qua Bộ Quy tắc Ứng xử dành cho nhà cung cấp; tiêu chí sàng lọc trong quy trình mua sắm và đấu thầu.] Đào tạo: Trong nội bộ VNA đã triển khai nhiều khóa đào tạo về thực thi các chính sách, cam kết như: về an toàn thông tin, giao tiếp và hợp tác trên môi trường số, Nâng cao nhận thức pháp luật về Bảo vệ dữ liệu cá nhân, ...
A21: 20 | B21: Quản trị | C21: GRI 2-25 | E21: Quy trình khắc phục các tác động tiêu cực | F21: 1. Cam kết của VNA về việc thực hiện hoặc hợp tác khắc phục các tác động tiêu cực mà VNA gây ra hoặc góp phần gây ra; 2. Mô tả cách tiếp cận của tổ chức trong việc xác định và giải quyết các khiếu nại, bao gồm cả các cơ chế giải quyết khiếu nại mà tổ chức đã thiết lập hoặc tham gia; 3. Các quy trình khắc phục khác ngoài cơ chế khiếu nại; 4. Mô tả cách thức các bên liên quan - với tư cách là người sử dụng cơ chế khiếu nại - tham gia vào quá trình thiết kế, rà soát, vận hành và cải tiến các cơ chế này; 5. Cách doanh nghiệp theo dõi tính hiệu quả của cơ chế khiếu nại và các quy trình khắc phục; ví dụ minh chứng về hiệu quả, kèm phản hồi của bên liên quan. | H21: Đáp ứng | I21: Tổ Thư ký | J21: Vietnam Airlines cam kết thực hiện hoặc hợp tác khắc phục các tác động tiêu cực mà Tổng công ty gây ra hoặc góp phần gây ra đối với các bên liên quan, trên cơ sở bảo vệ quyền và lợi ích hợp pháp của tổ chức, cá nhân và tuân thủ pháp luật hiện hành.
A22: 21 | B22: Quản trị | C22: GRI 2-26 | D22: =VLOOKUP(C22,'95 Chỉ tiêu'!$B$4:$K$98,5,0) -> #N/A | E22: Cơ chế tham vấn, phản ánh các vấn đề đạo đức | F22: 1. Cơ chế để cá nhân xin tư vấn về việc thực thi các chính sách và thông lệ ứng xử kinh doanh có trách nhiệm. 2. Cơ chế để cá nhân phản ánh quan ngại về hành vi kinh doanh của doanh nghiệp. | H22: Đáp ứng | I22: Tổ Thư ký | J22: Vietnam Airlines duy trì các cơ chế để cá nhân xin tư vấn và phản ánh quan ngại liên quan đến ứng xử kinh doanh có trách nhiệm. Xin tư vấn: người lao động và các bên liên quan có thể liên hệ Ban Pháp chế và các Ban chức năng để được hướng dẫn về việc áp dụng các quy định nội bộ và pháp luật liên quan trong hoạt động hằng ngày. Phản ánh quan ngại: Vietnam Airlines tiếp nhận và xử lý đơn thư khiếu nại, tố cáo, kiến nghị, phản ánh theo quy định của pháp luật Bảo mật và bảo vệ người tố giác: thông tin về người tố cáo được bảo mật theo quy định pháp luật; người tố cáo được bảo vệ và không bị trả đũa vì việc phản ánh trung thực.
A23: 22 | B23: Quản trị | C23: GRI 2-27 | E23: Tuân thủ pháp luật và các quy định | F23: Đây là chỉ tiêu định lượng - bốn tiểu mục đều yêu cầu số liệu, không phải cam kết: 1. TỔNG SỐ trường hợp không tuân thủ đáng kể phát sinh trong kỳ, chia theo: (i) số trường hợp bị phạt tiền; (ii) số trường hợp bị áp dụng chế tài phi tiền tệ. 2. TỔNG SỐ và GIÁ TRỊ TIỀN các khoản phạt ĐÃ NỘP trong kỳ, chia theo: (i) khoản phạt cho vi phạm phát sinh trong kỳ báo cáo; (ii) khoản phạt cho vi phạm phát sinh ở các kỳ trước. 3. Mô tả từng trường hợp không tuân thủ đáng kể (địa bàn, lĩnh vực, bối cảnh). 4. Mô tả cách thức xác định các trường hợp không tuân thủ nghiêm trọng | H23: No | I23: Tổ Thư ký | J23: Vietnam Airlines cam kết duy trì ở mức cao nhất các tiêu chuẩn đạo đức trong hoạt động sản xuất kinh doanh, đề cao tính chuyên nghiệp, trung thực và minh bạch. Bảo đảm tuân thủ các điều ước quốc tế, Hiến pháp và pháp luật luôn là ưu tiên quan trọng của Tổng công ty trong mọi hoạt động. Trong năm 2025, VNA không bị phạt hoặc áp dụng chế tài
A24: 23 | B24: Quản trị | C24: GRI 2-29 | D24: =VLOOKUP(C24,'95 Chỉ tiêu'!$B$4:$K$98,5,0) -> #N/A | E24: Tiếp cận đối thoại các bên liên quan | F24: 1. Danh mục các nhóm bên liên quan mà doanh nghiệp đối thoại và phương pháp nhận diện các nhóm này. 2. Mục đích đối thoại với từng nhóm 3. Cách doanh nghiệp đảm bảo đối thoại thực chất | H24: Đáp ứng | I24: Tổ Thư ký | J24: Vietnam Airlines xác định các nhóm bên liên quan trên cơ sở mức độ ảnh hưởng của hoạt động của TCT tới các nhóm này và mức độ ảnh hưởng của các nhóm này tới hoạt động của TCT. Mục đích đối thoại là nắm bắt kỳ vọng và mối quan tâm của từng nhóm, nhận diện các tác động thực tế và tiềm ẩn, và xác định các biện pháp phòng ngừa, giảm thiểu phù hợp. Các nhóm bên liên quan chính và kênh đối thoại bao gồm: • Cổ đông và nhà đầu tư: ĐHĐCĐ thường niên và bất thường; công bố thông tin định kỳ và bất thường theo quy định; gặp gỡ nhà đầu tư. • Khách hàng: các kênh tiếp nhận phản ánh, khiếu nại; khảo sát mức độ hài lòng; chương trình khách hàng thường xuyên; mạng xã hội. • Người lao động và Công đoàn: Hội nghị người lao động; đối thoại tại nơi làm việc; thương lượng tập thể; các kênh truyền thông nội bộ. • Cơ quan quản lý nhà nước: báo cáo định kỳ; làm việc với cơ quan đại diện chủ sở hữu và cơ quan quản lý chuyên ngành; tham gia góp ý xây dựng chính sách. • Nhà cung cấp và đối tác: đàm phán hợp đồng; đánh giá nhà cung cấp; hội nghị đối tác. • Cộng đồng: các chương trình cộng đồng và hoạt động an sinh xã hội. • Hiệp hội và liên minh ngành: tham gia IATA, AAPA, SkyTeam và Hiệp hội Doanh nghiệp Hàng không Việt Nam. • Cơ quan truyền thông: họp báo, thông cáo báo chí, kênh truyền thông chính thức.
A25: 24 | B25: Quản trị | C25: GRI 3-3 | D25: =VLOOKUP(C25,'95 Chỉ tiêu'!$B$4:$K$98,5,0) -> #N/A | E25: Quản lý các chủ đề trọng yếu | F25: LƯU Ý CẤU TRÚC: GRI 3-3 phải được báo cáo RIÊNG cho TỪNG chủ đề trọng yếu, không báo cáo gộp cho cả trụ cột. Trước 3-3 phải có GRI 3-1 (quy trình xác định chủ đề trọng yếu) và GRI 3-2 (danh mục chủ đề trọng yếu). i. Xác định các chủ đề trọng yếu thuộc trụ cột Governance. ii. Với mỗi chủ đề, công bố đủ 6 nội dung: (a) Mô tả các tác động thực tế và tiềm ẩn, tiêu cực và tích cực đối với kinh tế, môi trường và con người (kể cả quyền con người). (b) VNA có liên quan tới các tác động tiêu cực đó thông qua hoạt động của chính mình hay thông qua quan hệ kinh doanh — và mô tả hoạt động/quan hệ kinh doanh đó. (c) Các chính sách hoặc cam kết đối với chủ đề. (d) Các hành động quản lý chủ đề, gồm: (i) ngăn ngừa/giảm thiểu tác động tiêu cực tiềm ẩn; (ii) xử lý tác động tiêu cực thực tế, gồm thực hiện hoặc hợp tác khắc phục; (iii) quản lý tác động tích cực. (e) Theo dõi hiệu quả của các hành động, gồm: (i) quy trình theo dõi; (ii) mục tiêu, chỉ tiêu và chỉ số đánh giá tiến độ; (iii) mức độ hiệu quả đạt được, gồm tiến độ so với mục tiêu; (iv) bài học rút ra và cách đưa vào chính sách, quy trình vận hành. (f) Việc đối thoại với các bên liên quan đã định hình các hành động tại (d) và việc đánh giá hiệu quả tại (e) như thế nào. | H25: Đáp ứng | I25: Tổ Thư ký | J25: Đề xuất không đưa nội dung này lên website, vì cần báo cáo cụ thể cho 21 chỉ tiêu còn lại nên có thể trùng với các nội dung đã báo cáo
A26: 25 | B26: Quản trị | C26: GRI 201-4 | D26: =VLOOKUP(C26,'95 Chỉ tiêu'!$B$4:$K$98,5,0) -> #N/A | E26: Trợ cấp/tài trợ nhận từ chính phủ | F26: 1. TỔNG GIÁ TRỊ TIỀN TỆ hỗ trợ tài chính nhận được từ BẤT KỲ chính phủ nào trong kỳ, phân theo 08 loại: (i) miễn, giảm thuế và tín dụng thuế; (ii) trợ cấp; (iii) tài trợ đầu tư, tài trợ nghiên cứu và phát triển, các loại tài trợ khác; (iv) giải thưởng; (v) miễn/giảm tiền bản quyền, phí nhượng quyền; (vi) hỗ trợ tài chính từ các Cơ quan Tín dụng Xuất khẩu (ECA); (vii) ưu đãi tài chính; (viii) lợi ích tài chính khác đã nhận hoặc sẽ nhận từ bất kỳ chính phủ nào cho bất kỳ hoạt động nào 2. Số liệu tại mục (1) phân tách theo quốc gia 3. Chính phủ có hiện diện trong cơ cấu sở hữu hay không và mức độ hiện diện 4. Cơ sở xác định giá trị: áp dụng nhất quán các nguyên tắc kế toán được thừa nhận chung | H26: Đáp ứng | I26: Tổ Thư ký | J26: Sự hiện diện của Nhà nước trong cơ cấu sở hữu: Nhà nước là cổ đông chi phối của Vietnam Airlines, nắm giữ khoảng 86,42% vốn điều lệ thông qua Bộ Tài chính và Tổng công ty Đầu tư và Kinh doanh vốn nhà nước (SCIC). Nhà nước thực hiện các quyền và nghĩa vụ của cổ đông theo quy định của pháp luật và Điều lệ TCT. Hỗ trợ tài chính nhận từ Chính phủ: Thực hiện Nghị quyết số 135/2020/QH14 ngày 17/11/2020 của Quốc hội về các giải pháp tháo gỡ khó khăn cho TCTHKVN do ảnh hưởng của đại dịch COVID-19, Vietnam Airlines đã triển khai gói giải pháp thanh khoản quy mô 12.000 tỷ đồng, gồm: • Khoản vay tái cấp vốn 4.000 tỷ đồng thông qua các tổ chức tín dụng được Ngân hàng Nhà nước tái cấp vốn với lãi suất 0%/năm, không tài sản bảo đảm. Khoản vay đã được Quốc hội cho phép gia hạn trả nợ, tối đa đến ngày 31/12/2027. • Phương án phát hành cổ phiếu tăng vốn điều lệ quy mô khoảng 8.000 tỷ đồng, trong đó SCIC thay mặt Chính phủ thực hiện quyền mua cổ phần của cổ đông Nhà nước. Kiểm toán Nhà nước đã thực hiện kiểm toán việc sử dụng nguồn vốn của gói hỗ trợ và kết luận nguồn vốn được quản lý, sử dụng đúng mục đích đề ra.
A27: 26 | B27: Quản trị | C27: GRI 205-2 | D27: =VLOOKUP(C27,'95 Chỉ tiêu'!$B$4:$K$98,5,0) -> #N/A | E27: Truyền thông, đào tạo về chống tham nhũng | F27: Đây là chỉ tiêu định lượng, cụ thể: 1. Số lượng và tỷ lệ thành viên cơ quan quản trị đã được truyền thông về chính sách và quy trình phòng, chống tham nhũng — phân theo khu vực. 2. Số lượng và tỷ lệ người lao động đã được truyền thông — phân theo nhóm lao động và theo khu vực 3. Số lượng và tỷ lệ đối tác kinh doanh đã được truyền thông — phân theo nhóm lao động và theo khu vực; đồng thời mô tả nếu có truyền thông tới tổ chức/cá nhân khác. 4. Số lượng và tỷ lệ thành viên HĐQT đã được đào tạo về phòng, chống tham nhũng — phân theo khu vực. 5. Số lượng và tỷ lệ người lao động đã được đào tạo — phân theo nhóm lao động và khu vực. | H27: Đáp ứng | I27: Tổ Thư ký | J27: Trong năm 2025, Ban lãnh đạo Vietnam Airlines đã ban hành Chương trình Phòng, chống tham nhũng, tiêu cực, thực hành tiết kiệm, chống lãng phí — được xác định là kim chỉ nam trong mọi hoạt động sản xuất kinh doanh cũng như công tác quản trị nội bộ. Chương trình được triển khai theo Luật Phòng, chống tham nhũng 2018 và các quy định liên quan. -> Mục 1 và 2 đã đảm bảo tỷ lệ 100%
A28: 27 | B28: Quản trị | C28: GRI 205-3 | D28: =VLOOKUP(C28,'95 Chỉ tiêu'!$B$4:$K$98,5,0) -> #N/A | E28: Sự cố tham nhũng xác nhận và biện pháp xử lý | F28: 1. TỔNG SỐ và TÍNH CHẤT các sự cố tham nhũng ĐÃ ĐƯỢC XÁC NHẬN trong kỳ báo cáo. 2. (b) Tổng số sự cố đã xác nhận dẫn tới việc NGƯỜI LAO ĐỘNG bị sa thải hoặc bị kỷ luật vì hành vi tham nhũng. 3. (c) Tổng số sự cố đã xác nhận dẫn tới việc CHẤM DỨT hoặc KHÔNG GIA HẠN hợp đồng với đối tác kinh doanh do vi phạm liên quan đến tham nhũng. 4. (d) Các VỤ VIỆC PHÁP LÝ CÔNG KHAI về tham nhũng được khởi kiện đối với Tổng công ty hoặc người lao động của Tổng công ty trong kỳ, và KẾT QUẢ xử lý các vụ việc đó. | H28: No | I28: Tổ Thư ký | J28: Không có sự cố tham nhũng nào tại Vietnam Airlines
A29: 28 | B29: Quản trị | C29: GRI 206-1 | D29: =VLOOKUP(C29,'95 Chỉ tiêu'!$B$4:$K$98,5,0) -> #N/A | E29: Vụ kiện về cạnh tranh không lành mạnh, độc quyền | F29: 1. (a) SỐ VỤ KIỆN đang xử lý hoặc đã hoàn tất trong kỳ báo cáo liên quan đến hành vi hạn chế cạnh tranh và vi phạm pháp luật về chống độc quyền, trong đó doanh nghiệp được xác định là MỘT BÊN THAM GIA. 2. (b) KẾT QUẢ CHÍNH của các vụ kiện đã hoàn tất, bao gồm các quyết định hoặc phán quyết. | H29: No | I29: Tổ Thư ký | J29: Không có vụ kiện về cạnh tranh không lành mạnh, độc quyền nào tại Vietnam Airlines
A30: 29 | B30: Quản trị | C30: GRI 415-1 | D30: =VLOOKUP(C30,'95 Chỉ tiêu'!$B$4:$K$98,5,0) -> #N/A | E30: Đóng góp cho các hoạt động chính trị | F30: 1. (a) TỔNG GIÁ TRỊ TIỀN TỆ các khoản đóng góp chính trị bằng TIỀN và bằng HIỆN VẬT, được thực hiện TRỰC TIẾP và GIÁN TIẾP bởi doanh nghiệp — phân theo QUỐC GIA và theo BÊN NHẬN/THỤ HƯỞNG. 2. (b) Nếu có đóng góp bằng hiện vật: phương pháp ước tính giá trị. | H30: Đáp ứng | I30: Tổ Thư ký | J30: Là Hãng hàng không quốc gia, Vietnam Airlines phối hợp chặt chẽ với Chính phủ và các cơ quan quản lý trong quá trình xây dựng và hoàn thiện chính sách, pháp luật về hàng không dân dụng và phát triển bền vững. Tổng công ty cũng tham gia đóng góp ý kiến chính sách một cách gián tiếp thông qua các hiệp hội và liên minh ngành như IATA, AAPA, SkyTeam và Hiệp hội Doanh nghiệp Hàng không Việt Nam. Trong năm 2026, Vietnam Airlines đã chi 753.708 USD phí hội viên cho các hiệp hội và liên minh trên

Sheet 32 chỉ tiêu BC động
AF1: Thông tin nguồn | AL1: Báo cáo | AN1: Đưa ra landing page
A2: STT | B2: PIC CQĐV | C2: PIC VNA | D2: PIC (AQT) | E2: Mã GRI | F2: Trụ cột | G2: Chủ đề | H2: Tên chỉ tiêu | I2: Mã báo cáo | J2: Chỉ tiêu con/báo cáo (EN) | K2: Chỉ tiêu con/báo cáo (VI) | L2: Người cung cấp | M2: Định nghĩa / Diễn giải | N2: Logic/Công thức tính | O2: Đơn vị tính | P2: Nguồn dữ liệu thực tế | Q2: Tần suất cập nhật dữ liệu | R2: Chiều tổng hợp dữ liệu | S2: So sánh với lũy kế cùng kỳ | T2: So sánh với cùng kỳ | U2: So sánh với tháng trước | V2: So sánh với định mức | W2: So sánh với kế hoạch tháng | X2: So sánh với kế hoạch năm | Y2: So sánh với ngưỡng | Z2: So sánh các tháng trong năm | AA2: So sánh các quý trong năm | AB2: So sánh các năm | AC2: Mức độ ưu tiên (1: Rất cần thiết 2: Cần thiết 3: Bình thường 4: Chưa quan tâm 5: Có thể bị thay thế, loại bỏ) | AD2: Tài liệu/Form | AE2: Ghi chú | AF2: Bảng | AG2: Trường dữ liệu | AH2: Quy tắc lấy dữ liệu | AI2: Ghi chú của thông tin nguồn | AJ2: Tên báo cáo (EN) | AK2: Tên báo cáo (VN) | AL2: Tab | AM2: Loại biểu đồ
A3: 1 | B3: Tổ Khai thác | C3: MS Lê | D3: NhiPLH | E3: GRI 302-1 | F3: =VLOOKUP(E3,'95 Chỉ tiêu'!$B$4:$F$177,2,0) -> #N/A | G3: Energy and Emissions | H3: Năng lượng tiêu thụ trong tổ chức | I3: CT 1.1 | J3: Total Fuel Consumption | K3: Tổng nhiên liệu tiêu thụ | L3: Chị Lê | M3: - Tổng lượng nhiên liệu hàng không được ghi nhận tiêu thụ trong kỳ, được xác định dựa trên lượng nhiên liệu nạp vào tàu bay (fuel uplift) thay vì lượng nhiên liệu thực tế đốt cháy trong quá trình bay. - Toàn bộ nhiên liệu nạp cho chuyến bay sẽ được phân bổ vào ngày khởi hành của chuyến bay đó, bao gồm cả nhiên liệu sử dụng trong giai đoạn taxi out/in, kể cả đối với các chuyến bay kéo dài sang ngày hôm sau. - Nhiên liệu tiêu thụ bao gồm cả nhiên liệu Jet A-1 và nhiên liệu SAF nguyên chất; tuy nhiên không phải tất cả chuyến bay đều sử dụng SAF, do một số chuyến bay chỉ sử dụng 100% nhiên liệu Jet A-1 | N3: - Tổng nhiên liệu tiêu thụ = Tổng lượng nhiên liệu đã nạp trên tất cả chuyến bay theo hóa đơn | O3: - Lít | P3: - FIMS | Q3: - Hàng tháng (ngày cuối cùng trong tháng) | R3: - Năm | S3: N/A | T3: N/A | U3: N/A | V3: N/A | W3: N/A | X3: N/A | Y3: N/A | Z3: N/A | AA3: N/A | AB3: X | AC3: 1 | AD3: FLIGHT_INTERGRATED.xlsx | AF3: stg_fims.receipts | AG3: number_unit | AH3: Tổng hợp lượng tra nạp (uplift) dựa trên hóa đơn, gán theo ngày khởi hành (dep_dt). Đơn vị: Lít. | AJ3: Energy consumption within the organization | AK3: Năng lượng tiêu thụ trong tổ chức | AM3: Card
A4: 2 | B4: Tổ Khai thác | C4: MS Lê | D4: NhiPLH | E4: GRI 302-1 | F4: =VLOOKUP(E4,'95 Chỉ tiêu'!$B$4:$F$177,2,0) -> #N/A | G4: Energy and Emissions | H4: Năng lượng tiêu thụ trong tổ chức | I4: CT 1.2 | J4: Jet A-1 Fuel Consumption | K4: Nhiên liệu tiêu thụ Jet A-1 | L4: Chị Lê | M4: - Là tổng lượng nhiên liệu hàng không hóa thạch Jet A-1 được tra nạp và sử dụng cho hoạt động khai thác bay. | N4: - Nhiên liệu tiêu thụ Jet A-1 = Tổng nhiên liệu tiêu thụ - Lượng SAF nguyên chất. | O4: - Lít | P4: - Tổng nhiên liệu tiêu thụ: FIMS. - Nhiên liệu SAF nguyên chất: ANCM. | Q4: - Hàng tháng (ngày cuối cùng trong tháng) | R4: - Năm | S4: N/A | T4: N/A | U4: N/A | V4: N/A | W4: N/A | X4: N/A | Y4: N/A | Z4: N/A | AA4: N/A | AB4: N/A | AC4: 1 | AD4: https://vtxgroupvn.sharepoint.com/:x:/r/sites/v25gfx02639/_layouts/15/Doc.aspx?sourcedoc=%7B037CC2E8-12C6-41E4-A941-1E3E6132DE37%7D&file=FIMS.xlsx&action=default&mobileredirect=true | AF4: stg_fims.receipts | AG4: number_unit | AH4: - Lấy tổng nhiên liệu từ FIMS trừ đi lượng SAF nguyên chất (Neat SAF). Đơn vị: Lít. - Neat SAF: Lấy từ ANCM | AI4: Chưa có ANCM | AJ4: Energy consumption within the organization | AK4: Năng lượng tiêu thụ trong tổ chức | AM4: Card
A5: 3 | B5: Tổ Khai thác | C5: MS Lê | D5: NhiPLH | E5: GRI 302-1 | F5: =VLOOKUP(E5,'95 Chỉ tiêu'!$B$4:$F$177,2,0) -> #N/A | G5: Energy and Emissions | H5: Năng lượng tiêu thụ trong tổ chức | I5: CT 1.3 | J5: SAF Consumption | K5: Nhiên liệu tiêu thụ SAF | L5: Chị Lê | M5: - Nhiên liệu tiêu thụ SAF là phần SAF nguyên chất (Neat SAF). - Trên thực tế, tàu bay không sử dụng 100% SAF mà sử dụng nhiên liệu pha trộn giữa SAF và Jet A-1 theo tỷ lệ do nhà cung cấp hoặc quy định từng khu vực quy định. | N5: - Nhiên liệu tiêu thụ SAF = Tổng lượng SAF nguyên chất được xác định trong chứng nhận từ nhà cung cấp tại các sân bay. | O5: - Lít | P5: - ANCM | Q5: - Hàng tháng (ngày cuối cùng trong tháng) | R5: - Năm, Tháng | S5: N/A | T5: N/A | U5: N/A | V5: N/A | W5: N/A | X5: N/A | Y5: N/A | Z5: N/A | AA5: N/A | AB5: N/A | AC5: 1 | AF5: Nhập tay (ANCM) | AG5: N/A | AH5: Tổng hợp từ chứng nhận nạp SAF do nhà cung cấp cấp tại các sân bay quốc tế. Đơn vị: Lít. | AI5: Chưa có ANCM | AJ5: Energy consumption within the organization | AK5: Năng lượng tiêu thụ trong tổ chức | AM5: Card
A6: 4 | B6: Tổ Khai thác | C6: MS Lê | D6: NhiPLH | E6: GRI 302-1 | F6: =VLOOKUP(E6,'95 Chỉ tiêu'!$B$4:$F$177,2,0) -> #N/A | G6: Energy and Emissions | H6: Năng lượng tiêu thụ trong tổ chức | I6: CT 1.4 | J6: Fuel Type Distribution | K6: Tỷ lệ các loại nhiên liệu | L6: Chị Lê | M6: - Chỉ tiêu phản ánh tỷ trọng tiêu thụ của từng loại nhiên liệu trong tổng lượng nhiên liệu khai thác bay, bao gồm nhiên liệu Jet A-1 và nhiên liệu SAF. | N6: - Tỷ lệ nhiên liệu SAF = Lượng tiêu thụ nhiên liệu SAF/ Tổng lượng nhiên liệu tiêu thụ. - Tỷ lệ nhiên liệu Jet A-1 = Lượng tiêu thụ nhiên liệu Jet A-1/ Tổng lượng nhiên liệu tiêu thụ. | O6: - Lít | P6: - Tham chiếu nguồn dữ liệu của CT 1.2 và CT 1.3. | Q6: - Theo tháng hoặc theo năm (ngày cuối cùng trong tháng) | R6: - Năm | S6: N/A | T6: N/A | U6: N/A | V6: N/A | W6: N/A | X6: N/A | Y6: N/A | Z6: N/A | AA6: N/A | AB6: N/A | AC6: 2 | AF6: Thừa kế luồng | AG6: N/A | AH6: Tính toán tỷ lệ phần trăm (%) cho từng loại nhiên liệu trên tổng lượng tiêu thụ. | AI6: Chưa có ANCM | AJ6: Energy consumption within the organization | AK6: Năng lượng tiêu thụ trong tổ chức | AM6: Donut
A7: 5 | B7: Tổ Khai thác | C7: MS Lê | D7: NhiPLH | E7: GRI 302-1 | F7: =VLOOKUP(E7,'95 Chỉ tiêu'!$B$4:$F$177,2,0) -> #N/A | G7: Energy and Emissions | H7: Năng lượng tiêu thụ trong tổ chức | I7: CT 1.5 | J7: Neat SAF Consumption by Ratio | K7: Tiêu thụ SAF theo tỷ lệ pha trộn SAF | L7: Chị Lê | M7: - Tổng lượng nhiên liệu pha trộn SAF được phân loại theo các mức tỷ lệ pha trộn SAF khác nhau như 2%, 3%, 5%, 7%.... | N7: - Tỷ lệ pha trộn SAF được xác định dựa trên tỷ lệ giữa lượng SAF nguyên chất (Neat SAF) và tổng lượng nhiên liệu SAF pha trộn (Blended SAF), cụ thể: + Tỷ lệ pha trộn SAF (% Neat SAF) = Lượng SAF nguyên chất (Neat SAF) / Lượng SAF pha trộn (Blended SAF). | O7: - Lít | P7: - Nhiên liệu SAF nguyên chất, SAF pha trộn: ANCM | Q7: - Theo tháng hoặc theo năm (ngày cuối cùng trong tháng) | R7: - Năm | S7: N/A | T7: N/A | U7: N/A | V7: N/A | W7: N/A | X7: N/A | Y7: N/A | Z7: N/A | AA7: N/A | AB7: N/A | AC7: 2 | AD7: 01. DETAIL--POS-170-I-0226-VIETNAM-VN-DPS.pdf | AF7: Nhập tay (ANCM) | AG7: N/A | AH7: Bóc tách từ chứng từ nạp nhiên liệu tại từng sân bay. | AI7: Chưa có ANCM | AJ7: Energy consumption within the organization | AK7: Năng lượng tiêu thụ trong tổ chức | AM7: Donut
A8: 6 | B8: Tổ Khai thác | C8: MS Lê | D8: NhiPLH | E8: GRI 302-1 | F8: =VLOOKUP(E8,'95 Chỉ tiêu'!$B$4:$F$177,2,0) -> #N/A | G8: Energy and Emissions | H8: Năng lượng tiêu thụ trong tổ chức | I8: CT 1.6 | J8: Annual Fuel Consumption vs Target | K8: Tiêu thụ nhiên liệu theo năm so với mục tiêu (Lít) | L8: Chị Lê | M8: - Tổng lượng nhiên liệu tiêu thụ thực tế theo từng năm và so sánh với mức mục tiêu tiêu thụ nhiên liệu đã được kế hoạch hoặc hãng hàng không đặt ra. - Dữ liệu bao gồm tổng lượng nhiên liệu Jet A-1 và nhiên liệu SAF sử dụng cho hoạt động khai thác bay trong năm báo cáo. | N8: - Tổng nhiên liệu tiêu thụ theo năm = Tổng lượng tiêu thụ Jet A-1 + Tổng lượng tiêu thụ SAF (theo năm). - So sánh giữa giá trị thực tế và giá trị mục tiêu theo từng năm báo cáo. | O8: - Lít | P8: - Tham chiếu nguồn dữ liệu của CT 1.2 và CT 1.3. | Q8: - Cuối năm (ngày cuối cùng trong năm) | R8: - Năm | S8: N/A | T8: N/A | U8: N/A | V8: N/A | W8: N/A | X8: X | Y8: N/A | Z8: N/A | AA8: N/A | AB8: X | AC8: 1 | AF8: stg_khnh.fls_ops | AG8: fuel | AH8: So sánh lũy kế thực hiện năm với mục tiêu tiêu thụ nhiên liệu lấy từ PMS | AJ8: Energy consumption within the organization | AK8: Năng lượng tiêu thụ trong tổ chức | AM8: Combo chart
A9: 7 | B9: Tổ Khai thác | C9: MS Lê | D9: NhiPLH | E9: GRI 302-1 | F9: =VLOOKUP(E9,'95 Chỉ tiêu'!$B$4:$F$177,2,0) -> #N/A | G9: Energy and Emissions | H9: Năng lượng tiêu thụ trong tổ chức | I9: CT 1.7 | J9: Monthly Fuel Consumption in the Current Year | K9: Tiêu thụ nhiên liệu theo tháng trong năm hiện tại (Lít) | L9: Chị Lê | M9: - Tổng lượng nhiên liệu tiêu thụ theo từng tháng trong năm hiện tại phục vụ hoạt động khai thác bay. - Dữ liệu bao gồm cả nhiên liệu Jet A-1 và nhiên liệu SAF được sử dụng trong kỳ báo cáo. | N9: - Tổng nhiên liệu tiêu thụ theo tháng = Tổng lượng tiêu thụ Jet A-1 + Tổng lượng tiêu thụ SAF trong tháng tương ứng. - Dữ liệu được tổng hợp và hiển thị theo từng tháng của năm hiện tại. | O9: - Lít | P9: - Tham chiếu nguồn dữ liệu của CT 1.2 và CT 1.3.P12 | Q9: - Hàng tháng (ngày cuối cùng trong tháng). | R9: - Năm, Tháng | S9: N/A | T9: X | U9: N/A | V9: N/A | W9: N/A | X9: N/A | Y9: N/A | Z9: X | AA9: N/A | AB9: N/A | AC9: 2 | AF9: Thừa kế luồng | AG9: N/A | AH9: Tổng hợp dữ liệu hiển thị theo chu kỳ tháng để so sánh biến động cùng kỳ. Đơn vị: Lít. | AI9: Chưa có ANCM | AJ9: Energy consumption within the organization | AK9: Năng lượng tiêu thụ trong tổ chức | AM9: Stacked column
A10: 8 | B10: Tổ Khai thác | C10: MS Lê | D10: NhiPLH | E10: GRI 302-1 | F10: =VLOOKUP(E10,'95 Chỉ tiêu'!$B$4:$F$177,2,0) -> #N/A | G10: Energy and Emissions | H10: Năng lượng tiêu thụ trong tổ chức | I10: CT 1.8 | J10: Annual Jet A-1 Fuel Consumption Trend | K10: Tiêu thụ nhiên liệu Jet A-1 qua các năm | L10: Chị Lê | M10: - Tổng lượng nhiên liệu tiêu thụ Jet A-1 trong 10 năm gần nhất. | N10: - Nhiên liệu tiêu thụ Jet A-1 = Tổng nhiên liệu tiêu thụ - Lượng SAF nguyên chất. | O10: - Lít | P10: - Tham chiếu nguồn dữ liệu của CT 1.2 và CT 1.3.P12 | Q10: - Hàng tháng (ngày cuối cùng trong tháng). | R10: - Năm, Tháng | S10: N/A | T10: N/A | U10: N/A | V10: N/A | W10: N/A | X10: N/A | Y10: N/A | Z10: N/A | AA10: N/A | AB10: N/A | AC10: 2 | AF10: Thừa kế luồng
